Workbook
Name _Hlk503351175: WizdomActuals!$I$4
Name _Hlk517339798: Expenses!$B$2

Sheet Forecast
E2: Inflation Rate | F2: 0.03 | H2: Non-zero (CPI or inflation rate) show of money in TODAY'S dollars. Set to zero if future values do not want to account for inflation
E3: Jeff Net Tax Rate | F3: 0.29
E4: Tin Net Tax Rate | F4: 0.19
R5: 60 yrs | Y5: 67 | AG5: 75
D6: 2026 | E6: =D6+1 -> 2027 | F6: =E6+1 -> 2028 | G6: =F6+1 -> 2029 | H6: =G6+1 -> 2030 | I6: =H6+1 -> 2031 | J6: =I6+1 -> 2032 | K6: =J6+1 -> 2033 | L6: =K6+1 -> 2034 | ... AG6: =AF6+1 -> 2055
C7: Net Cashflow | D7: =SUM(D13:D20) -> 66980.625 | E7: =SUM(E13:E32) -> 17535.609 | F7: =SUM(F13:F32) -> 21110.789 | G7: =SUM(G13:G32) -> 14609.613 | H7: =SUM(H13:H32) -> 18198.015 | I7: =SUM(I13:I32) -> 35232.925 | J7: =SUM(J13:J32) -> 57674.492 | K7: =SUM(K13:K32) -> 79574.156 | L7: =SUM(L13:L32) -> 84616.975 | ... AG7: =SUM(AG13:AG32) -> 385420.8
C8: Net Wealth | D8: =D7+SUM(D38:D47)+D33 -> 3623680.6 | E8: =E7+SUM(E38:E47)+E33 -> 1789442.4 | F8: =F7+SUM(F38:F47)+F33 -> 2031405.7 | G8: =G7+SUM(G38:G47)+G33 -> 2277646 | H8: =H7+SUM(H38:H47)+H33 -> 2548873.8 | I8: =I7+SUM(I38:I47)+I33 -> 2846362.5 | J8: =J7+SUM(J38:J47)+J33 -> 3148352.5 | K8: =K7+SUM(K38:K47)+K33 -> 3466639.9 | ... AG8: =AG7+SUM(AG38:AG47)+AG33 -> 16781418
D12: Sum of 2026 | E12: Sum of 2027 | F12: Sum of 2028 | G12: Sum of 2029 | H12: Sum of 2030 | I12: Sum of 2031 | J12: Sum of 2032 | K12: Sum of 2033 | L12: Sum of 2034 | M12: Sum of 2035 | N12: Sum of 2036 | O12: Sum of 2037 | P12: Sum of 2038 | Q12: Sum of 2039 | R12: Sum of 2040 | S12: Sum of 2041 | T12: Sum of 2042 | U12: Sum of 2043 | V12: Sum of 2044 | W12: Sum of 2045 | X12: Sum of 2046 | Y12: Sum of 2047 | Z12: Sum of 2048 | AA12: Sum of 2049 | AB12: Sum of 2050 | AC12: Sum of 2051 | AD12: Sum of 2052 | AE12: Sum of 2053 | AF12: Sum of 2054 | AG12: Sum of 2055
C13: Jeff | D13: 222332.3 | E13: 181833.72 | F13: 189243.46 | G13: 197132.95 | H13: 205142.01 | I13: 239835.84 | J13: 248236.25 | K13: 257127.22 | L13: 266187.12 | M13: 275534.71 | N13: 285082.05 | O13: 295130.64 | P13: 305408.14 | Q13: 316019.89 | R13: 326901.16 | S13: 338293.9 | T13: 349988.76 | U13: 362073.79 | V13: 374513.93 | W13: 387474.77 | X13: 400827.48 | Y13: 414637.94 | Z13: 428845.78 | AA13: 441676.39 | AB13: 453987.91 | AC13: 466648.73 | AD13: 479664.2 | AE13: 493062.44 | AF13: 506773.15 | AG13: 520077.93
C14: Magiting | D14: 41620.8 | E14: -15570.313 | F14: -13528.343 | G14: -11077.196 | H14: -8673.5641 | I14: -6161.2749 | J14: -3683.2492 | K14: -797.51477 | L14: 2075.2832 | M14: 5081.2913 | N14: 8094.5927 | O14: 11512.927 | P14: 14962.038 | Q14: 18575.139 | R14: 22248.18 | S14: 26321.927 | T14: 30481.821 | U14: 34844.397 | V14: 39333.733 | W14: 44217.208 | X14: 49257.098 | Y14: 54548.432 | Z14: 60051.469 | AA14: 65939.075 | AB14: 72072.412 | AC14: 78518.787 | AD14: 85285.01 | AE14: 91863.709 | AF14: 95225.38 | AG14: 98082.142
C15: Tin | D15: 96368.578 | E15: 84442.682 | F15: 87146.865 | G15: 90006.34 | H15: 92909.781 | I15: 95897.048 | J15: 98934.123 | K15: 102131.82 | L15: 105387.35 | M15: 108738.36 | N15: 112154.9 | O15: 115737.7 | P15: 119394.83 | Q15: 123161.11 | R15: 127011.77 | S15: 131034.54 | T15: 135151.43 | U15: 139393.55 | V15: 143742.74 | W15: 148270.08 | X15: 152915.35 | Y15: 157704.89 | Z15: 162628.32 | AA15: 167716.73 | AB15: 172941.58 | AC15: 178331.43 | AD15: 183886.81 | AE15: 189630.9 | AF15: 195488.3 | AG15: 200735.43
C17: Jeff Tax | D17: =-1*$F$3*D13 -> -64476.368 | E17: =-1*$F$3*E13 -> -52731.778 | F17: =-1*$F$3*F13 -> -54880.603 | G17: =-1*$F$3*G13 -> -57168.554 | H17: =-1*$F$3*H13 -> -59491.184 | I17: =-1*$F$3*I13 -> -69552.395 | J17: =-1*$F$3*J13 -> -71988.513 | K17: =-1*$F$3*K13 -> -74566.893 | ... AG17: =-1*$F$3*AG13 -> -150822.6
C18: Tin Tax | D18: =-1*$F$3*D15 -> -27946.888 | E18: =-1*$F$3*E15 -> -24488.378 | F18: =-1*$F$3*F15 -> -25272.591 | G18: =-1*$F$3*G15 -> -26101.839 | H18: =-1*$F$3*H15 -> -26943.837 | I18: =-1*$F$3*I15 -> -27810.144 | J18: =-1*$F$3*J15 -> -28690.896 | K18: =-1*$F$3*K15 -> -29618.228 | ... AG18: =-1*$F$3*AG15 -> -58213.274
C19: Repayments | D19: -105678 | E19: =-1*SUMPRODUCT((E6=Repayments!$AZ$49:$CC$49)*(Repayments!$AZ$50:$CC$50)) -> -47853.327 | F19: =-1*SUMPRODUCT((F6=Repayments!$AZ$49:$CC$49)*(Repayments!$AZ$50:$CC$50)) -> -50558.094 | G19: =-1*SUMPRODUCT((G6=Repayments!$AZ$49:$CC$49)*(Repayments!$AZ$50:$CC$50)) -> -54110.983 | H19: =-1*SUMPRODUCT((H6=Repayments!$AZ$49:$CC$49)*(Repayments!$AZ$50:$CC$50)) -> -57551.961 | I19: =-1*SUMPRODUCT((I6=Repayments!$AZ$49:$CC$49)*(Repayments!$AZ$50:$CC$50)) -> -59567.123 | J19: =-1*SUMPRODUCT((J6=Repayments!$AZ$49:$CC$49)*(Repayments!$AZ$50:$CC$50)) -> -44411.925 | K19: =-1*SUMPRODUCT((K6=Repayments!$AZ$49:$CC$49)*(Repayments!$AZ$50:$CC$50)) -> -47569.306 | L19: =-1*SUMPRODUCT((L6=Repayments!$AZ$49:$CC$49)*(Repayments!$AZ$50:$CC$50)) -> -50629.249 | ... AG19: =-1*SUMPRODUCT((AG6=Repayments!$AZ$49:$CC$49)*(Repayments!$AZ$50:$CC$50)) -> 0
C20: Expenses | D20: =-12*SUMPRODUCT((D6=Expenses!$J$2:$AM$2)*(Expenses!$J$3:$AM$41)) -> -95239.8 | E20: =-12*SUMPRODUCT((E6=Expenses!$J$2:$AM$2)*(Expenses!$J$3:$AM$41)) -> -98096.994 | F20: =-12*SUMPRODUCT((F6=Expenses!$J$2:$AM$2)*(Expenses!$J$3:$AM$41)) -> -101039.9 | G20: =-12*SUMPRODUCT((G6=Expenses!$J$2:$AM$2)*(Expenses!$J$3:$AM$41)) -> -104071.1 | H20: =-12*SUMPRODUCT((H6=Expenses!$J$2:$AM$2)*(Expenses!$J$3:$AM$41)) -> -107193.23 | I20: =-12*SUMPRODUCT((I6=Expenses!$J$2:$AM$2)*(Expenses!$J$3:$AM$41)) -> -110409.03 | J20: =-12*SUMPRODUCT((J6=Expenses!$J$2:$AM$2)*(Expenses!$J$3:$AM$41)) -> -113721.3 | K20: =-12*SUMPRODUCT((K6=Expenses!$J$2:$AM$2)*(Expenses!$J$3:$AM$41)) -> -117132.94 | ... AG20: =-12*SUMPRODUCT((AG6=Expenses!$J$2:$AM$2)*(Expenses!$J$3:$AM$41)) -> -224438.83
B22: Scenarios | C22: Jarvih Uni | E22: -10000 | F22: -10000 | G22: -10000 | H22: -10000 | I22: -7000 | J22: -7000
C23: Jeci Uni | G23: -10000 | H23: -10000 | I23: -10000 | J23: -10000
C24: Aiah Uni | I24: -10000 | J24: -10000 | K24: -10000 | L24: -10000
C25: Jeran Uni
C26: Japan Trip
C27: Fiji Cruise
C33: Liabilities | D33: =-1*SUMPRODUCT((D6=Repayments!$AZ$12:$CC$12)*(Repayments!$AZ$13:$CC$13)) -> 0 | E33: =-1*SUMPRODUCT((E6=Repayments!$AZ$12:$CC$12)*(Repayments!$AZ$13:$CC$13)) -> -1962440.7 | F33: =-1*SUMPRODUCT((F6=Repayments!$AZ$12:$CC$12)*(Repayments!$AZ$13:$CC$13)) -> -1911882.6 | G33: =-1*SUMPRODUCT((G6=Repayments!$AZ$12:$CC$12)*(Repayments!$AZ$13:$CC$13)) -> -1857771.6 | H33: =-1*SUMPRODUCT((H6=Repayments!$AZ$12:$CC$12)*(Repayments!$AZ$13:$CC$13)) -> -1800219.6 | I33: =-1*SUMPRODUCT((I6=Repayments!$AZ$12:$CC$12)*(Repayments!$AZ$13:$CC$13)) -> -1742007.4 | J33: =-1*SUMPRODUCT((J6=Repayments!$AZ$12:$CC$12)*(Repayments!$AZ$13:$CC$13)) -> -1697595.4 | K33: =-1*SUMPRODUCT((K6=Repayments!$AZ$12:$CC$12)*(Repayments!$AZ$13:$CC$13)) -> -1650026.1 | ... AG33: =-1*SUMPRODUCT((AG6=Repayments!$AZ$12:$CC$12)*(Repayments!$AZ$13:$CC$13)) -> 0
B37: Owner | C37: Type | D37: Sum of 2026 | E37: Sum of 2027 | F37: Sum of 2028 | G37: Sum of 2029 | H37: Sum of 2030 | I37: Sum of 2031 | J37: Sum of 2032 | K37: Sum of 2033 | L37: Sum of 2034 | M37: Sum of 2035 | N37: Sum of 2036 | O37: Sum of 2037 | P37: Sum of 2038 | Q37: Sum of 2039 | R37: Sum of 2040 | S37: Sum of 2041 | T37: Sum of 2042 | U37: Sum of 2043 | V37: Sum of 2045 | W37: Sum of 2044 | X37: Sum of 2046 | Y37: Sum of 2047 | Z37: Sum of 2048 | AA37: Sum of 2049 | AB37: Sum of 2050 | AC37: Sum of 2051 | AD37: Sum of 2052 | AE37: Sum of 2053 | AF37: Sum of 2054 | AG37: Sum of 2055
B38: Jeff | C38: Super | D38: 426700 | E38: 457422.4 | F38: 490356.81 | G38: 525662.5 | H38: 563510.2 | I38: 604082.94 | J38: 647576.91 | K38: 694202.45 | L38: 744185.02 | M38: 797766.35 | N38: 855205.52 | O38: 916780.32 | P38: 982788.5 | Q38: 1053549.3 | R38: 1129404.8 | S38: 1210722 | T38: 1297894 | U38: 1391342.3 | V38: 1598908.3 | W38: 1491519 | X38: 1714029.7 | Y38: 1837439.9 | Z38: 1969735.5 | AA38: 2111556.5 | AB38: 2263588.6 | AC38: 2426566.9 | AD38: 2601279.8 | AE38: 2788571.9 | AF38: 2989349.1 | AG38: 3204582.2
B39: Joint | C39: Property | D39: 1930000 | E39: 2004925 | F39: 2083500.6 | G39: 2165926.3 | H39: 2252412.9 | I39: 2343183.4 | J39: 2438473.6 | K39: 2538533.1 | L39: 2643625.8 | M39: 2754030.6 | N39: 2870043 | O39: 2991975.4 | P39: 3120158.1 | Q39: 3254941 | R39: 3396694.1 | S39: 3545808.8 | T39: 3702699.6 | U39: 3867804.9 | V39: 4224542.4 | W39: 4041588.8 | X39: 4417185.5 | Y39: 4620068.4 | Z39: 4833773.5 | AA39: 5058917.4 | AB39: 5296152.5 | AC39: 5546169.9 | AD39: 5809700.9 | AE39: 6087520 | AF39: 6380447 | AG39: 6689349.9
B40: Magiting | C40: Property | D40: 1200000 | E40: 1272000 | F40: 1348320 | G40: 1429219.2 | H40: 1514972.4 | I40: 1605870.7 | J40: 1702222.9 | K40: 1804356.3 | L40: 1912617.7 | M40: 2027374.8 | N40: 2149017.2 | O40: 2277958.3 | P40: 2414635.8 | Q40: 2559513.9 | R40: 2713084.7 | S40: 2875869.8 | T40: 3048422 | U40: 3231327.3 | V40: 3630719.4 | W40: 3425207 | X40: 3848562.6 | Y40: 4079476.3 | Z40: 4324244.9 | AA40: 4583699.6 | AB40: 4858721.6 | AC40: 5150244.9 | AD40: 5459259.6 | AE40: 5786815.1 | AF40: 6134024 | AG40: 6502065.5

Sheet Income
V1: 60 yrs | AC1: 67 | AK1: 75
B2: Owner | C2: % Own | D2: Type | E2: Name | F2: Annual | G2: Growth | H2: 2026 | I2: =H2+1 -> 2027 | J2: =I2+1 -> 2028 | K2: =J2+1 -> 2029 | L2: =K2+1 -> 2030 | M2: =L2+1 -> 2031 | N2: =M2+1 -> 2032 | O2: =N2+1 -> 2033 | P2: =O2+1 -> 2034 | ... AK2: =AJ2+1 -> 2055
B3: Jeff | C3: 1 | D3: PAYG | E3: PAYG | F3: 190026 | G3: 0.025 | H3: =F3 -> 190026 | I3: =H3*(1+$G3) -> 194776.65 | J3: =I3*(1+$G3) -> 199646.07 | K3: =J3*(1+$G3) -> 204637.22 | L3: =K3*(1+$G3) -> 209753.15 | M3: =L3*(1+$G3) -> 214996.98 | N3: =M3*(1+$G3) -> 220371.9 | O3: =N3*(1+$G3) -> 225881.2 | P3: =O3*(1+$G3) -> 231528.23 | ... AK3: =AJ3*(1+$G3) -> 388870.61
B4: Tin | C4: 1 | D4: PAYG | E4: PAYG | F4: 85000 | G4: 0.025 | H4: =F4 -> 85000 | I4: =H4*(1+$G4) -> 87125 | J4: =I4*(1+$G4) -> 89303.125 | K4: =J4*(1+$G4) -> 91535.703 | L4: =K4*(1+$G4) -> 93824.096 | M4: =L4*(1+$G4) -> 96169.698 | N4: =M4*(1+$G4) -> 98573.941 | O4: =N4*(1+$G4) -> 101038.29 | P4: =O4*(1+$G4) -> 103564.25 | ... AK4: =AJ4*(1+$G4) -> 173944.63
B5: Jeff | C5: 1 | D5: PAYG | E5: Jeff - STVR 2025 | F5: 23287.5 | G5: 0.025 | H5: =F5 -> 23287.5 | I5: =H5*(1+$G5) -> 23869.687 | J5: =I5*(1+$G5) -> 24466.43 | K5: =J5*(1+$G5) -> 25078.09 | L5: =K5*(1+$G5) -> 25705.043 | M5: =L5*(1+$G5) -> 26347.669 | N5: =M5*(1+$G5) -> 27006.36 | O5: =N5*(1+$G5) -> 27681.519 | P5: =O5*(1+$G5) -> 28373.557 | ... AK5: =AJ5*(1+$G5) -> 47655.712
B6: Jeff | C6: 0.5 | D6: Rental Income | E6: Black Diamond | F6: =620*52*C6 -> 16120 | G6: 0.03 | H6: =F6 -> 16120 | I6: =H6*(1+$G6) -> 16603.6 | J6: =I6*(1+$G6) -> 17101.708 | K6: =J6*(1+$G6) -> 17614.759 | L6: =K6*(1+$G6) -> 18143.202 | M6: =L6*(1+$G6) -> 18687.498 | N6: =M6*(1+$G6) -> 19248.123 | O6: =N6*(1+$G6) -> 19825.567 | P6: =O6*(1+$G6) -> 20420.334 | ... AK6: =AJ6*(1+$G6) -> 37987.836
B7: Tin | C7: 0.5 | D7: Rental Income | E7: Black Diamond | F7: =620*52*C7 -> 16120 | G7: 0.03 | H7: =F7 -> 16120 | I7: =H7*(1+$G7) -> 16603.6 | J7: =I7*(1+$G7) -> 17101.708 | K7: =J7*(1+$G7) -> 17614.759 | L7: =K7*(1+$G7) -> 18143.202 | M7: =L7*(1+$G7) -> 18687.498 | N7: =M7*(1+$G7) -> 19248.123 | O7: =N7*(1+$G7) -> 19825.567 | P7: =O7*(1+$G7) -> 20420.334 | ... AK7: =AJ7*(1+$G7) -> 37987.836
B8: Jeff | C8: 0.99 | D8: Rental Income | E8: Wentworthville | F8: =685*52*C8 -> 35263.8 | G8: 0.03 | H8: =F8 -> 35263.8 | I8: =H8*(1+$G8) -> 36321.714 | J8: =I8*(1+$G8) -> 37411.365 | K8: =J8*(1+$G8) -> 38533.706 | L8: =K8*(1+$G8) -> 39689.718 | M8: =L8*(1+$G8) -> 40880.409 | N8: =M8*(1+$G8) -> 42106.821 | O8: =N8*(1+$G8) -> 43370.026 | P8: =O8*(1+$G8) -> 44671.127 | ... AK8: =AJ8*(1+$G8) -> 83101.455
B9: Tin | C9: 0.01 | D9: Rental Income | E9: Wentworthville | F9: =685*52*C9 -> 356.2 | G9: 0.03 | H9: =F9 -> 356.2 | I9: =H9*(1+$G9) -> 366.886 | J9: =I9*(1+$G9) -> 377.89258 | K9: =J9*(1+$G9) -> 389.22936 | L9: =K9*(1+$G9) -> 400.90624 | M9: =L9*(1+$G9) -> 412.93343 | N9: =M9*(1+$G9) -> 425.32143 | O9: =N9*(1+$G9) -> 438.08107 | P9: =O9*(1+$G9) -> 451.2235 | ... AK9: =AJ9*(1+$G9) -> 839.40863
B10: Jeff | C10: 1 | D10: SG Fleet Lease | E10: Carnival | F10: =-52*((436.56+580.21)/2) -> -26436.02 | H10: =$F$10 -> -26436.02 | I10: =$F$10 -> -26436.02 | J10: =$F$10 -> -26436.02 | K10: =$F$10 -> -26436.02 | L10: =$F$10 -> -26436.02
B11: Jeff | C11: -0.5 | D11: Rental Running Costs | E11: Black Diamond | F11: =620*52*C11*0.31 -> -4997.2 | G11: 0.03 | H11: =F11 -> -4997.2 | I11: =H11*(1+$G11) -> -5147.116 | J11: =I11*(1+$G11) -> -5301.5295 | K11: =J11*(1+$G11) -> -5460.5754 | L11: =K11*(1+$G11) -> -5624.3926 | M11: =L11*(1+$G11) -> -5793.1244 | N11: =M11*(1+$G11) -> -5966.9181 | O11: =N11*(1+$G11) -> -6145.9257 | P11: =O11*(1+$G11) -> -6330.3035 | ... AK11: =AJ11*(1+$G11) -> -11776.229
B12: Tin | C12: -0.5 | D12: Rental Running Costs | E12: Black Diamond | F12: =620*52*C12*0.31 -> -4997.2 | G12: 0.03 | H12: =F12 -> -4997.2 | I12: =H12*(1+$G12) -> -5147.116 | J12: =I12*(1+$G12) -> -5301.5295 | K12: =J12*(1+$G12) -> -5460.5754 | L12: =K12*(1+$G12) -> -5624.3926 | M12: =L12*(1+$G12) -> -5793.1244 | N12: =M12*(1+$G12) -> -5966.9181 | O12: =N12*(1+$G12) -> -6145.9257 | P12: =O12*(1+$G12) -> -6330.3035 | ... AK12: =AJ12*(1+$G12) -> -11776.229
B13: Jeff | C13: -0.99 | D13: Rental Running Costs | E13: Wentworthville | F13: =685*52*C13*0.31 -> -10931.778 | G13: 0.03 | H13: =F13 -> -10931.778 | I13: =H13*(1+$G13) -> -11259.731 | J13: =I13*(1+$G13) -> -11597.523 | K13: =J13*(1+$G13) -> -11945.449 | L13: =K13*(1+$G13) -> -12303.812 | M13: =L13*(1+$G13) -> -12672.927 | N13: =M13*(1+$G13) -> -13053.115 | O13: =N13*(1+$G13) -> -13444.708 | P13: =O13*(1+$G13) -> -13848.049 | ... AK13: =AJ13*(1+$G13) -> -25761.451
B14: Tin | C14: -0.01 | D14: Rental Running Costs | E14: Wentworthville | F14: =685*52*C14*0.31 -> -110.422 | G14: 0.03 | H14: =F14 -> -110.422 | I14: =H14*(1+$G14) -> -113.73466 | J14: =I14*(1+$G14) -> -117.1467 | K14: =J14*(1+$G14) -> -120.6611 | L14: =K14*(1+$G14) -> -124.28093 | M14: =L14*(1+$G14) -> -128.00936 | N14: =M14*(1+$G14) -> -131.84964 | O14: =N14*(1+$G14) -> -135.80513 | P14: =O14*(1+$G14) -> -139.87929 | ... AK14: =AJ14*(1+$G14) -> -260.21668
B15: Jeff | C15: -0.5 | D15: Rental Interest Expense | E15: Black Diamond | H15: =Forecast!$F$3*$C15*SUMPRODUCT((H$2=Repayments!$AZ$37:$CC$37)*(Repayments!$AZ$38:$CC$38)) -> 0 | I15: =$C15*SUMPRODUCT((I$2=Repayments!$AZ$37:$CC$37)*(Repayments!$AZ$38:$CC$38)) -> -14060.289 | J15: =$C15*SUMPRODUCT((J$2=Repayments!$AZ$37:$CC$37)*(Repayments!$AZ$38:$CC$38)) -> -13892.39 | K15: =$C15*SUMPRODUCT((K$2=Repayments!$AZ$37:$CC$37)*(Repayments!$AZ$38:$CC$38)) -> -13636.435 | L15: =$C15*SUMPRODUCT((L$2=Repayments!$AZ$37:$CC$37)*(Repayments!$AZ$38:$CC$38)) -> -13402.86 | M15: =$C15*SUMPRODUCT((M$2=Repayments!$AZ$37:$CC$37)*(Repayments!$AZ$38:$CC$38)) -> -13154.41 | N15: =$C15*SUMPRODUCT((N$2=Repayments!$AZ$37:$CC$37)*(Repayments!$AZ$38:$CC$38)) -> -12926.102 | O15: =$C15*SUMPRODUCT((O$2=Repayments!$AZ$37:$CC$37)*(Repayments!$AZ$38:$CC$38)) -> -12611.323 | P15: =$C15*SUMPRODUCT((P$2=Repayments!$AZ$37:$CC$37)*(Repayments!$AZ$38:$CC$38)) -> -12312.463 | ... AK15: =$C15*SUMPRODUCT((AK$2=Repayments!$AZ$37:$CC$37)*(Repayments!$AZ$38:$CC$38)) -> 0
B16: Tin | C16: -0.5 | D16: Rental Interest Expense | E16: Black Diamond | H16: =Forecast!$F$3*$C16*SUMPRODUCT((H$2=Repayments!$AZ$37:$CC$37)*(Repayments!$AZ$38:$CC$38)) -> 0 | I16: =$C16*SUMPRODUCT((I$2=Repayments!$AZ$37:$CC$37)*(Repayments!$AZ$38:$CC$38)) -> -14060.289 | J16: =$C16*SUMPRODUCT((J$2=Repayments!$AZ$37:$CC$37)*(Repayments!$AZ$38:$CC$38)) -> -13892.39 | K16: =$C16*SUMPRODUCT((K$2=Repayments!$AZ$37:$CC$37)*(Repayments!$AZ$38:$CC$38)) -> -13636.435 | L16: =$C16*SUMPRODUCT((L$2=Repayments!$AZ$37:$CC$37)*(Repayments!$AZ$38:$CC$38)) -> -13402.86 | M16: =$C16*SUMPRODUCT((M$2=Repayments!$AZ$37:$CC$37)*(Repayments!$AZ$38:$CC$38)) -> -13154.41 | N16: =$C16*SUMPRODUCT((N$2=Repayments!$AZ$37:$CC$37)*(Repayments!$AZ$38:$CC$38)) -> -12926.102 | O16: =$C16*SUMPRODUCT((O$2=Repayments!$AZ$37:$CC$37)*(Repayments!$AZ$38:$CC$38)) -> -12611.323 | P16: =$C16*SUMPRODUCT((P$2=Repayments!$AZ$37:$CC$37)*(Repayments!$AZ$38:$CC$38)) -> -12312.463 | ... AK16: =$C16*SUMPRODUCT((AK$2=Repayments!$AZ$37:$CC$37)*(Repayments!$AZ$38:$CC$38)) -> 0
B17: Jeff | C17: -0.99 | D17: Rental Interest Expense | E17: Wentworthville | H17: =Forecast!$F$3*$C17*SUMPRODUCT((H$2=Repayments!$AZ$31:$CC$31)*(Repayments!$AZ$32:$CC$32)) -> 0 | I17: =$C17*SUMPRODUCT((I$2=Repayments!$AZ$31:$CC$31)*(Repayments!$AZ$32:$CC$32)) -> -32834.778 | J17: =$C17*SUMPRODUCT((J$2=Repayments!$AZ$31:$CC$31)*(Repayments!$AZ$32:$CC$32)) -> -32154.646 | K17: =$C17*SUMPRODUCT((K$2=Repayments!$AZ$31:$CC$31)*(Repayments!$AZ$32:$CC$32)) -> -31252.349 | L17: =$C17*SUMPRODUCT((L$2=Repayments!$AZ$31:$CC$31)*(Repayments!$AZ$32:$CC$32)) -> -30382.012 | M17: =$C17*SUMPRODUCT((M$2=Repayments!$AZ$31:$CC$31)*(Repayments!$AZ$32:$CC$32)) -> -29456.247 | N17: =$C17*SUMPRODUCT((N$2=Repayments!$AZ$31:$CC$31)*(Repayments!$AZ$32:$CC$32)) -> -28550.818 | O17: =$C17*SUMPRODUCT((O$2=Repayments!$AZ$31:$CC$31)*(Repayments!$AZ$32:$CC$32)) -> -27429.136 | P17: =$C17*SUMPRODUCT((P$2=Repayments!$AZ$31:$CC$31)*(Repayments!$AZ$32:$CC$32)) -> -26315.313 | ... AK17: =$C17*SUMPRODUCT((AK$2=Repayments!$AZ$31:$CC$31)*(Repayments!$AZ$32:$CC$32)) -> 0
B18: Tin | C18: -0.01 | D18: Rental Interest Expense | E18: Wentworthville | H18: =Forecast!$F$3*$C18*SUMPRODUCT((H$2=Repayments!$AZ$31:$CC$31)*(Repayments!$AZ$32:$CC$32)) -> 0 | I18: =$C18*SUMPRODUCT((I$2=Repayments!$AZ$31:$CC$31)*(Repayments!$AZ$32:$CC$32)) -> -331.66442 | J18: =$C18*SUMPRODUCT((J$2=Repayments!$AZ$31:$CC$31)*(Repayments!$AZ$32:$CC$32)) -> -324.79441 | K18: =$C18*SUMPRODUCT((K$2=Repayments!$AZ$31:$CC$31)*(Repayments!$AZ$32:$CC$32)) -> -315.68029 | L18: =$C18*SUMPRODUCT((L$2=Repayments!$AZ$31:$CC$31)*(Repayments!$AZ$32:$CC$32)) -> -306.88901 | M18: =$C18*SUMPRODUCT((M$2=Repayments!$AZ$31:$CC$31)*(Repayments!$AZ$32:$CC$32)) -> -297.53785 | N18: =$C18*SUMPRODUCT((N$2=Repayments!$AZ$31:$CC$31)*(Repayments!$AZ$32:$CC$32)) -> -288.39211 | O18: =$C18*SUMPRODUCT((O$2=Repayments!$AZ$31:$CC$31)*(Repayments!$AZ$32:$CC$32)) -> -277.06198 | P18: =$C18*SUMPRODUCT((P$2=Repayments!$AZ$31:$CC$31)*(Repayments!$AZ$32:$CC$32)) -> -265.81124 | ... AK18: =$C18*SUMPRODUCT((AK$2=Repayments!$AZ$31:$CC$31)*(Repayments!$AZ$32:$CC$32)) -> 0
B19: Magiting | C19: 1 | D19: Rental Income | E19: Shane St (Main) | F19: =700*52*C19 -> 36400 | G19: 0.03 | H19: =F19 -> 36400 | I19: =H19*(1+$G19) -> 37492 | J19: =I19*(1+$G19) -> 38616.76 | K19: =J19*(1+$G19) -> 39775.263 | L19: =K19*(1+$G19) -> 40968.521 | M19: =L19*(1+$G19) -> 42197.576 | N19: =M19*(1+$G19) -> 43463.504 | O19: =N19*(1+$G19) -> 44767.409 | P19: =O19*(1+$G19) -> 46110.431 | ... AK19: =AJ19*(1+$G19) -> 85778.984
B20: Magiting | C20: 1 | D20: Rental Income | E20: Shane St (Granny) | F20: =460*52*C20 -> 23920 | G20: 0.03 | H20: =F20 -> 23920 | I20: =H20*(1+$G20) -> 24637.6 | J20: =I20*(1+$G20) -> 25376.728 | K20: =J20*(1+$G20) -> 26138.03 | L20: =K20*(1+$G20) -> 26922.171 | M20: =L20*(1+$G20) -> 27729.836 | N20: =M20*(1+$G20) -> 28561.731 | O20: =N20*(1+$G20) -> 29418.583 | P20: =O20*(1+$G20) -> 30301.14 | ... AK20: =AJ20*(1+$G20) -> 56369.047
B21: Hernandez Accountants | C21: 1 | D21: Self Employed Income | E21: F1 Tax - Company Income | F21: =40000*C21 -> 40000 | G21: 0.05 | H21: =F21 -> 40000 | I21: =H21*(1+$G21) -> 42000 | J21: =I21*(1+$G21) -> 44100 | K21: =J21*(1+$G21) -> 46305 | L21: =K21*(1+$G21) -> 48620.25 | M21: =L21*(1+$G21) -> 51051.263 | N21: =M21*(1+$G21) -> 53603.826 | O21: =N21*(1+$G21) -> 56284.017 | P21: =O21*(1+$G21) -> 59098.218 | ... AK21: =AJ21*(1+$G21) -> 164645.42
B22: Hernandez Accountants | C22: 0.33 | D22: Self Employed Income | E22: Gravitax - Company Income | F22: =40000*C22 -> 13200 | G22: 0.05 | H22: =F22 -> 13200 | I22: =H22*(1+$G22) -> 13860 | J22: =I22*(1+$G22) -> 14553 | K22: =J22*(1+$G22) -> 15280.65 | L22: =K22*(1+$G22) -> 16044.683 | M22: =L22*(1+$G22) -> 16846.917 | N22: =M22*(1+$G22) -> 17689.262 | O22: =N22*(1+$G22) -> 18573.726 | P22: =O22*(1+$G22) -> 19502.412 | ... AK22: =AJ22*(1+$G22) -> 54332.99
B23: Magiting | C23: -1 | D23: Rental Running Costs | E23: Shane St (Main) | F23: =700*52*C23*0.31 -> -11284 | G23: 0.03 | H23: =F23 -> -11284 | I23: =H23*(1+$G23) -> -11622.52 | J23: =I23*(1+$G23) -> -11971.196 | K23: =J23*(1+$G23) -> -12330.331 | L23: =K23*(1+$G23) -> -12700.241 | M23: =L23*(1+$G23) -> -13081.249 | N23: =M23*(1+$G23) -> -13473.686 | O23: =N23*(1+$G23) -> -13877.897 | P23: =O23*(1+$G23) -> -14294.234 | ... AK23: =AJ23*(1+$G23) -> -26591.485
B24: Magiting | C24: -1 | D24: Rental Running Costs | E24: Shane St (Granny) | F24: =460*52*C24*0.31 -> -7415.2 | G24: 0.03 | H24: =F24 -> -7415.2 | I24: =H24*(1+$G24) -> -7637.656 | J24: =I24*(1+$G24) -> -7866.7857 | K24: =J24*(1+$G24) -> -8102.7893 | L24: =K24*(1+$G24) -> -8345.8729 | M24: =L24*(1+$G24) -> -8596.2491 | N24: =M24*(1+$G24) -> -8854.1366 | O24: =N24*(1+$G24) -> -9119.7607 | P24: =O24*(1+$G24) -> -9393.3535 | ... AK24: =AJ24*(1+$G24) -> -17474.405
B25: Magiting | C25: -1 | D25: Rental Interest Expense | E25: Shane St | H25: =$C25*SUMPRODUCT((H$2=Repayments!$AZ$43:$CC$43)*(Repayments!$AZ$44:$CC$44)) -> 0 | I25: =$C25*SUMPRODUCT((I$2=Repayments!$AZ$43:$CC$43)*(Repayments!$AZ$44:$CC$44)) -> -58439.737 | J25: =$C25*SUMPRODUCT((J$2=Repayments!$AZ$43:$CC$43)*(Repayments!$AZ$44:$CC$44)) -> -57683.85 | K25: =$C25*SUMPRODUCT((K$2=Repayments!$AZ$43:$CC$43)*(Repayments!$AZ$44:$CC$44)) -> -56557.368 | L25: =$C25*SUMPRODUCT((L$2=Repayments!$AZ$43:$CC$43)*(Repayments!$AZ$44:$CC$44)) -> -55518.141 | M25: =$C25*SUMPRODUCT((M$2=Repayments!$AZ$43:$CC$43)*(Repayments!$AZ$44:$CC$44)) -> -54411.189 | N25: =$C25*SUMPRODUCT((N$2=Repayments!$AZ$43:$CC$43)*(Repayments!$AZ$44:$CC$44)) -> -53380.661 | O25: =$C25*SUMPRODUCT((O$2=Repayments!$AZ$43:$CC$43)*(Repayments!$AZ$44:$CC$44)) -> -51985.849 | ... AK25: =$C25*SUMPRODUCT((AK$2=Repayments!$AZ$43:$CC$43)*(Repayments!$AZ$44:$CC$44)) -> 0

Sheet Assets
V1: 60 yrs | AC1: 67 | AK1: 75
B2: Owner | C2: Type | D2: Name | E2: Acquire Value | F2: Current Value | G2: Value Growth | H2: 2026 | I2: =H2+1 -> 2027 | J2: =I2+1 -> 2028 | K2: =J2+1 -> 2029 | L2: =K2+1 -> 2030 | M2: =L2+1 -> 2031 | N2: =M2+1 -> 2032 | O2: =N2+1 -> 2033 | P2: =O2+1 -> 2034 | ... AK2: =AJ2+1 -> 2055
B3: Jeff | C3: Super | D3: Mercer | F3: 213500 | G3: 0.072 | H3: =F3 -> 213500 | I3: =H3*(1+$G3) -> 228872 | J3: =I3*(1+$G3) -> 245350.78 | K3: =J3*(1+$G3) -> 263016.04 | L3: =K3*(1+$G3) -> 281953.2 | M3: =L3*(1+$G3) -> 302253.83 | N3: =M3*(1+$G3) -> 324016.1 | O3: =N3*(1+$G3) -> 347345.26 | P3: =O3*(1+$G3) -> 372354.12 | ... AK3: =AJ3*(1+$G3) -> 1603417.6
B4: Jeff | C4: Super | D4: ART | F4: 213200 | G4: 0.072 | H4: =F4 -> 213200 | I4: =H4*(1+$G4) -> 228550.4 | J4: =I4*(1+$G4) -> 245006.03 | K4: =J4*(1+$G4) -> 262646.46 | L4: =K4*(1+$G4) -> 281557.01 | M4: =L4*(1+$G4) -> 301829.11 | N4: =M4*(1+$G4) -> 323560.81 | O4: =N4*(1+$G4) -> 346857.19 | P4: =O4*(1+$G4) -> 371830.9 | ... AK4: =AJ4*(1+$G4) -> 1601164.6
B5: Joint | C5: SMSF | F5: 10888 | G5: 0.06 | H5: =F5 -> 10888 | I5: =H5*(1+$G5) -> 11541.28 | J5: =I5*(1+$G5) -> 12233.757 | K5: =J5*(1+$G5) -> 12967.782 | L5: =K5*(1+$G5) -> 13745.849 | M5: =L5*(1+$G5) -> 14570.6 | N5: =M5*(1+$G5) -> 15444.836 | O5: =N5*(1+$G5) -> 16371.526 | P5: =O5*(1+$G5) -> 17353.818 | ... AK5: =AJ5*(1+$G5) -> 58995.407
B6: Joint | C6: Property | D6: 4/10 Abraham Street, Rooty Hill, New South Wales, 2766 | E6: =405000+17000+1500+1000 -> 424500 | F6: 850000 | G6: 0.06 | H6: =F6 -> 850000 | I6: =H6*(1+$G6) -> 901000 | J6: =I6*(1+$G6) -> 955060 | K6: =J6*(1+$G6) -> 1012363.6 | L6: =K6*(1+$G6) -> 1073105.4 | M6: =L6*(1+$G6) -> 1137491.7 | N6: =M6*(1+$G6) -> 1205741.2 | O6: =N6*(1+$G6) -> 1278085.7 | P6: =O6*(1+$G6) -> 1354770.9 | ... AK6: =AJ6*(1+$G6) -> 4605629.7
B7: Joint | C7: Property | D7: 4/304 Great Western Highway Way, Wentworthville, New South Wales, 2145 | E7: =590000+24000+2000+1500 -> 617500 | F7: 565000 | G7: 0.015 | H7: =F7 -> 565000 | I7: =H7*(1+$G7) -> 573475 | J7: =I7*(1+$G7) -> 582077.12 | K7: =J7*(1+$G7) -> 590808.28 | L7: =K7*(1+$G7) -> 599670.41 | M7: =L7*(1+$G7) -> 608665.46 | N7: =M7*(1+$G7) -> 617795.44 | O7: =N7*(1+$G7) -> 627062.38 | P7: =O7*(1+$G7) -> 636468.31 | ... AK7: =AJ7*(1+$G7) -> 870088.99
B8: Joint | C8: Property | D8: 403/335 Anketell Street, Greenway, Australian Capital Territory, 2900 | E8: =489000+11500+2500+3000 -> 506000 | F8: 515000 | G8: 0.03 | H8: =F8 -> 515000 | I8: =H8*(1+$G8) -> 530450 | J8: =I8*(1+$G8) -> 546363.5 | K8: =J8*(1+$G8) -> 562754.41 | L8: =K8*(1+$G8) -> 579637.04 | M8: =L8*(1+$G8) -> 597026.15 | N8: =M8*(1+$G8) -> 614936.93 | O8: =N8*(1+$G8) -> 633385.04 | P8: =O8*(1+$G8) -> 652386.59 | ... AK8: =AJ8*(1+$G8) -> 1213631.2
B9: Magiting | C9: Property | D9: 8 Shane Street, Colyton, New South Wales, 2760 | E9: =920000+37000+3000+1500 -> 961500 | F9: 1200000 | G9: 0.06 | H9: =F9 -> 1200000 | I9: =H9*(1+$G9) -> 1272000 | J9: =I9*(1+$G9) -> 1348320 | K9: =J9*(1+$G9) -> 1429219.2 | L9: =K9*(1+$G9) -> 1514972.4 | M9: =L9*(1+$G9) -> 1605870.7 | N9: =M9*(1+$G9) -> 1702222.9 | O9: =N9*(1+$G9) -> 1804356.3 | P9: =O9*(1+$G9) -> 1912617.7 | ... AK9: =AJ9*(1+$G9) -> 6502065.5
B10: Jeff | C10: Bank Account | D10: Jeff Offset WW xx9474 | F10: 38331.49
B11: Joint | C11: Bank Account | D11: RH Offset xx5182 | F11: 60679.23
B12: Joint | C12: Bank Account | D12: RH Offset xx5190 | F12: 21747.04
B13: Tin | C13: Bank Account | D13: Tin - Cash xx5865 | F13: 936.68
B14: Tin | C14: Bank Account | D14: Tin - Rent and Salary xx1575 | F14: 3323
B15: Joint | C15: Bank Account | D15: WW Offset xx6867 | F15: 47864.37
B16: Joint | C16: Bank Account | D16: BD Offset xx1893 | F16: 36081.46
B17: Magiting | C17: Bank Account | D17: Magiting Inv Trustee xx2243 | F17: 979.42
B18: Jeff | C18: Shares | D18: WBC Shares (Tradeable) | F18: 6617
B19: Jeff | C19: Shares | D19: CBA Shares (ESS) | F19: 30123
B20: Jeff | C20: Shares | D20: CBA Shares (Renounceable Rights Allotment) | F20: 325
B21: Joint | C21: Managed Fund | D21: Futurity / ASG Education Bond Fund xx3689 | F21: 51148.45

Sheet Liabilities
A1: Snapshot as of June 30, 2026
A2: Property | B2: Owner | C2: Type | D2: Name | E2: Owing | F2: Limit | G2: Interest Rate | H2: Monthly Repayment
A3: 4/10 Abraham Street, Rooty Hill, New South Wales, 2766 | B3: Jeffrey Hernandez, Cristina Hernandez | C3: Property Loan | D3: RH Fixed Loan xx5182 | E3: 60679.23 | F3: 343000 | G3: 0.0603 | H3: 1469
A4: 4/10 Abraham Street, Rooty Hill, New South Wales, 2766 | B4: Jeffrey Hernandez, Cristina Hernandez | C4: Property Loan | D4: RH Loan x5190 | E4: 21747.04 | F4: 29000 | G4: 0.0603 | H4: 169
A5: 4/10 Abraham Street, Rooty Hill, New South Wales, 2766 | B5: Jeffrey Hernandez, Cristina Hernandez | C5: Property Loan | D5: WW RH xx4508 Top-up | E5: 22942.48 | F5: 30000 | G5: 0.0612 | H5: 167
A6: 4/10 Abraham Street, Rooty Hill, New South Wales, 2766 | B6: Jeffrey Hernandez, Cristina Hernandez | C6: Property Loan | D6: BD RH xx1893 Top-up | E6: 35595.46 | F6: 39500 | G6: 0.0619 | H6: 243
A7: 4/10 Abraham Street, Rooty Hill, New South Wales, 2766 | B7: Cristina Hernandez, Jeffrey Hernandez | C7: Property Loan | D7: WW RH xx6867 Top-up | E7: 98748.05 | F7: 113500 | G7: 0.0619 | H7: 690
A8: 4/10 Abraham Street, Rooty Hill, New South Wales, 2766 | B8: Jeffrey Hernandez, Cristina Hernandez | C8: Property Loan | D8: SH RH xx9773 Top-up | E8: 216411.23 | F8: 224000 | G8: 0.0608 | H8: 1340
A9: 403/335 Anketell Street, Greenway, Australian Capital Territory, 2900 | B9: Jeffrey Hernandez, Cristina Hernandez | C9: Property Loan | D9: BD xx4741 | E9: 421568.8 | F9: 440500 | G9: 0.0619 | H9: 2641
A10: 4/304 Great Western Highway Way, Wentworthville, New South Wales, 2145 | B10: Jeffrey Hernandez, Cristina Hernandez | C10: Property Loan | D10: WW xx9474 | E10: 419560.91 | F10: 472000 | G10: 0.0619 | H10: 2924
A11: 8 Shane Street, Colyton, New South Wales, 2760 | B11: Magiting Investments Pty Ltd | C11: Property Loan | D11: SH xx4901 | E11: 713040.78 | F11: 735787 | G11: 0.0633 | H11: 4702
C12: Lease | D12: SG Fleet | E12: 74171 | F12: 0 | G12: 0.0613 | H12: 1303
B13: Jeffrey Hernandez, Cristina Hernandez | C13: Credit Card or Store Card | D13: CBA Ultimate Awards | E13: 0 | F13: 12000 | G13: 0 | H13: 0

Sheet Expenses
X1: 60 yrs | AE1: 67 | AM1: 75
B2: Type | C2: Description | D2: Amount | E2: Frequency | F2: Monthly Total | J2: 2026 | K2: =J2+1 -> 2027 | L2: =K2+1 -> 2028 | M2: =L2+1 -> 2029 | N2: =M2+1 -> 2030 | O2: =N2+1 -> 2031 | P2: =O2+1 -> 2032 | Q2: =P2+1 -> 2033 | R2: =Q2+1 -> 2034 | ... AM2: =AL2+1 -> 2055
B3: Food Expenses | J3: =F3 -> 0 | K3: =J3*(1+Forecast!$F$2) -> 0 | L3: =K3*(1+Forecast!$F$2) -> 0 | M3: =L3*(1+Forecast!$F$2) -> 0 | N3: =M3*(1+Forecast!$F$2) -> 0 | O3: =N3*(1+Forecast!$F$2) -> 0 | P3: =O3*(1+Forecast!$F$2) -> 0 | Q3: =P3*(1+Forecast!$F$2) -> 0 | R3: =Q3*(1+Forecast!$F$2) -> 0 | ... AM3: =AL3*(1+Forecast!$F$2) -> 0
C4: Food & Supermarket | D4: 580 | E4: Weekly | F4: 2513.33 | J4: =F4 -> 2513.33 | K4: =J4*(1+Forecast!$F$2) -> 2588.7299 | L4: =K4*(1+Forecast!$F$2) -> 2666.3918 | M4: =L4*(1+Forecast!$F$2) -> 2746.3836 | N4: =M4*(1+Forecast!$F$2) -> 2828.7751 | O4: =N4*(1+Forecast!$F$2) -> 2913.6383 | P4: =O4*(1+Forecast!$F$2) -> 3001.0475 | Q4: =P4*(1+Forecast!$F$2) -> 3091.0789 | R4: =Q4*(1+Forecast!$F$2) -> 3183.8112 | ... AM4: =AL4*(1+Forecast!$F$2) -> 5922.8268
C5: Coffees, lunches & takeaways | D5: 560 | E5: Monthly | F5: 560 | J5: =F5 -> 560 | K5: =J5*(1+Forecast!$F$2) -> 576.8 | L5: =K5*(1+Forecast!$F$2) -> 594.104 | M5: =L5*(1+Forecast!$F$2) -> 611.92712 | N5: =M5*(1+Forecast!$F$2) -> 630.28493 | O5: =N5*(1+Forecast!$F$2) -> 649.19348 | P5: =O5*(1+Forecast!$F$2) -> 668.66929 | Q5: =P5*(1+Forecast!$F$2) -> 688.72936 | R5: =Q5*(1+Forecast!$F$2) -> 709.39125 | ... AM5: =AL5*(1+Forecast!$F$2) -> 1319.6767
C6: Cigarettes & alcohol | D6: 0 | E6: 0 | F6: 0 | J6: =F6 -> 0 | K6: =J6*(1+Forecast!$F$2) -> 0 | L6: =K6*(1+Forecast!$F$2) -> 0 | M6: =L6*(1+Forecast!$F$2) -> 0 | N6: =M6*(1+Forecast!$F$2) -> 0 | O6: =N6*(1+Forecast!$F$2) -> 0 | P6: =O6*(1+Forecast!$F$2) -> 0 | Q6: =P6*(1+Forecast!$F$2) -> 0 | R6: =Q6*(1+Forecast!$F$2) -> 0 | ... AM6: =AL6*(1+Forecast!$F$2) -> 0
B7: Discretionary Expenses | J7: =F7 -> 0 | K7: =J7*(1+Forecast!$F$2) -> 0 | L7: =K7*(1+Forecast!$F$2) -> 0 | M7: =L7*(1+Forecast!$F$2) -> 0 | N7: =M7*(1+Forecast!$F$2) -> 0 | O7: =N7*(1+Forecast!$F$2) -> 0 | P7: =O7*(1+Forecast!$F$2) -> 0 | Q7: =P7*(1+Forecast!$F$2) -> 0 | R7: =Q7*(1+Forecast!$F$2) -> 0 | ... AM7: =AL7*(1+Forecast!$F$2) -> 0
C8: Entertainment | D8: 500 | E8: Annually | F8: 41.67 | J8: =F8 -> 41.67 | K8: =J8*(1+Forecast!$F$2) -> 42.9201 | L8: =K8*(1+Forecast!$F$2) -> 44.207703 | M8: =L8*(1+Forecast!$F$2) -> 45.533934 | N8: =M8*(1+Forecast!$F$2) -> 46.899952 | O8: =N8*(1+Forecast!$F$2) -> 48.306951 | P8: =O8*(1+Forecast!$F$2) -> 49.756159 | Q8: =P8*(1+Forecast!$F$2) -> 51.248844 | R8: =Q8*(1+Forecast!$F$2) -> 52.786309 | ... AM8: =AL8*(1+Forecast!$F$2) -> 98.198085
C9: Domestic holidays | D9: 8500 | E9: Annually | F9: 708.33 | J9: =F9 -> 708.33 | K9: =J9*(1+Forecast!$F$2) -> 729.5799 | L9: =K9*(1+Forecast!$F$2) -> 751.4673 | M9: =L9*(1+Forecast!$F$2) -> 774.01132 | N9: =M9*(1+Forecast!$F$2) -> 797.23166 | O9: =N9*(1+Forecast!$F$2) -> 821.14861 | P9: =O9*(1+Forecast!$F$2) -> 845.78306 | Q9: =P9*(1+Forecast!$F$2) -> 871.15656 | R9: =Q9*(1+Forecast!$F$2) -> 897.29125 | ... AM9: =AL9*(1+Forecast!$F$2) -> 1669.226
C10: Clothing, shoes & accessories | D10: 0 | E10: Annually | F10: 0 | J10: =F10 -> 0 | K10: =J10*(1+Forecast!$F$2) -> 0 | L10: =K10*(1+Forecast!$F$2) -> 0 | M10: =L10*(1+Forecast!$F$2) -> 0 | N10: =M10*(1+Forecast!$F$2) -> 0 | O10: =N10*(1+Forecast!$F$2) -> 0 | P10: =O10*(1+Forecast!$F$2) -> 0 | Q10: =P10*(1+Forecast!$F$2) -> 0 | R10: =Q10*(1+Forecast!$F$2) -> 0 | ... AM10: =AL10*(1+Forecast!$F$2) -> 0
C11: Hairdressing & grooming | D11: 800 | E11: Annually | F11: 66.67 | J11: =F11 -> 66.67 | K11: =J11*(1+Forecast!$F$2) -> 68.6701 | L11: =K11*(1+Forecast!$F$2) -> 70.730203 | M11: =L11*(1+Forecast!$F$2) -> 72.852109 | N11: =M11*(1+Forecast!$F$2) -> 75.037672 | O11: =N11*(1+Forecast!$F$2) -> 77.288803 | P11: =O11*(1+Forecast!$F$2) -> 79.607467 | Q11: =P11*(1+Forecast!$F$2) -> 81.995691 | R11: =Q11*(1+Forecast!$F$2) -> 84.455561 | ... AM11: =AL11*(1+Forecast!$F$2) -> 157.11222
C12: Phone, Internet & pay TV | D12: 240 | E12: Monthly | F12: 240 | J12: =F12 -> 240 | K12: =J12*(1+Forecast!$F$2) -> 247.2 | L12: =K12*(1+Forecast!$F$2) -> 254.616 | M12: =L12*(1+Forecast!$F$2) -> 262.25448 | N12: =M12*(1+Forecast!$F$2) -> 270.12211 | O12: =N12*(1+Forecast!$F$2) -> 278.22578 | P12: =O12*(1+Forecast!$F$2) -> 286.57255 | Q12: =P12*(1+Forecast!$F$2) -> 295.16973 | R12: =Q12*(1+Forecast!$F$2) -> 304.02482 | ... AM12: =AL12*(1+Forecast!$F$2) -> 565.57572
C13: Media streaming & subscription services | D13: 20 | E13: Monthly | F13: 20 | J13: =F13 -> 20 | K13: =J13*(1+Forecast!$F$2) -> 20.6 | L13: =K13*(1+Forecast!$F$2) -> 21.218 | M13: =L13*(1+Forecast!$F$2) -> 21.85454 | N13: =M13*(1+Forecast!$F$2) -> 22.510176 | O13: =N13*(1+Forecast!$F$2) -> 23.185481 | P13: =O13*(1+Forecast!$F$2) -> 23.881046 | Q13: =P13*(1+Forecast!$F$2) -> 24.597477 | R13: =Q13*(1+Forecast!$F$2) -> 25.335402 | ... AM13: =AL13*(1+Forecast!$F$2) -> 47.13131
C14: Gifts & celebrations | D14: 1000 | E14: Annually | F14: 83.33 | J14: =F14 -> 83.33 | K14: =J14*(1+Forecast!$F$2) -> 85.8299 | L14: =K14*(1+Forecast!$F$2) -> 88.404797 | M14: =L14*(1+Forecast!$F$2) -> 91.056941 | N14: =M14*(1+Forecast!$F$2) -> 93.788649 | O14: =N14*(1+Forecast!$F$2) -> 96.602309 | P14: =O14*(1+Forecast!$F$2) -> 99.500378 | Q14: =P14*(1+Forecast!$F$2) -> 102.48539 | R14: =Q14*(1+Forecast!$F$2) -> 105.55995 | ... AM14: =AL14*(1+Forecast!$F$2) -> 196.3726
C15: Other discretionary expenses | D15: 0 | E15: Annually | F15: 0 | J15: =F15 -> 0 | K15: =J15*(1+Forecast!$F$2) -> 0 | L15: =K15*(1+Forecast!$F$2) -> 0 | M15: =L15*(1+Forecast!$F$2) -> 0 | N15: =M15*(1+Forecast!$F$2) -> 0 | O15: =N15*(1+Forecast!$F$2) -> 0 | P15: =O15*(1+Forecast!$F$2) -> 0 | Q15: =P15*(1+Forecast!$F$2) -> 0 | R15: =Q15*(1+Forecast!$F$2) -> 0 | ... AM15: =AL15*(1+Forecast!$F$2) -> 0
C16: Pets | D16: 0 | E16: 0 | F16: 0 | J16: =F16 -> 0 | K16: =J16*(1+Forecast!$F$2) -> 0 | L16: =K16*(1+Forecast!$F$2) -> 0 | M16: =L16*(1+Forecast!$F$2) -> 0 | N16: =M16*(1+Forecast!$F$2) -> 0 | O16: =N16*(1+Forecast!$F$2) -> 0 | P16: =O16*(1+Forecast!$F$2) -> 0 | Q16: =P16*(1+Forecast!$F$2) -> 0 | R16: =Q16*(1+Forecast!$F$2) -> 0 | ... AM16: =AL16*(1+Forecast!$F$2) -> 0
B17: Children and Education Expenses | J17: =F17 -> 0 | K17: =J17*(1+Forecast!$F$2) -> 0 | L17: =K17*(1+Forecast!$F$2) -> 0 | M17: =L17*(1+Forecast!$F$2) -> 0 | N17: =M17*(1+Forecast!$F$2) -> 0 | O17: =N17*(1+Forecast!$F$2) -> 0 | P17: =O17*(1+Forecast!$F$2) -> 0 | Q17: =P17*(1+Forecast!$F$2) -> 0 | R17: =Q17*(1+Forecast!$F$2) -> 0 | ... AM17: =AL17*(1+Forecast!$F$2) -> 0
C18: Public education costs | D18: 1600 | E18: Annually | F18: 133.33 | J18: =F18 -> 133.33 | K18: =J18*(1+Forecast!$F$2) -> 137.3299 | L18: =K18*(1+Forecast!$F$2) -> 141.4498 | M18: =L18*(1+Forecast!$F$2) -> 145.69329 | N18: =M18*(1+Forecast!$F$2) -> 150.06409 | O18: =N18*(1+Forecast!$F$2) -> 154.56601 | P18: =O18*(1+Forecast!$F$2) -> 159.20299 | Q18: =P18*(1+Forecast!$F$2) -> 163.97908 | R18: =Q18*(1+Forecast!$F$2) -> 168.89845 | ... AM18: =AL18*(1+Forecast!$F$2) -> 314.20088
C19: Private education costs | D19: 15640 | E19: Annually | F19: 1303.33 | J19: =F19 -> 1303.33 | K19: =J19*(1+Forecast!$F$2) -> 1342.4299 | L19: =K19*(1+Forecast!$F$2) -> 1382.7028 | M19: =L19*(1+Forecast!$F$2) -> 1424.1839 | N19: =M19*(1+Forecast!$F$2) -> 1466.9094 | O19: =N19*(1+Forecast!$F$2) -> 1510.9167 | P19: =O19*(1+Forecast!$F$2) -> 1556.2442 | Q19: =P19*(1+Forecast!$F$2) -> 1602.9315 | R19: =Q19*(1+Forecast!$F$2) -> 1651.0195 | ... AM19: =AL19*(1+Forecast!$F$2) -> 3071.3825
C20: Tertiary & vocational education | D20: 820 | E20: Monthly | F20: 820 | J20: =F20 -> 820 | K20: =J20*(1+Forecast!$F$2) -> 844.6 | L20: =K20*(1+Forecast!$F$2) -> 869.938 | M20: =L20*(1+Forecast!$F$2) -> 896.03614 | N20: =M20*(1+Forecast!$F$2) -> 922.91722 | O20: =N20*(1+Forecast!$F$2) -> 950.60474 | P20: =O20*(1+Forecast!$F$2) -> 979.12288 | Q20: =P20*(1+Forecast!$F$2) -> 1008.4966 | R20: =Q20*(1+Forecast!$F$2) -> 1038.7515 | ... AM20: =AL20*(1+Forecast!$F$2) -> 1932.3837
C21: Childcare | D21: 0 | E21: 0 | F21: 0 | J21: =F21 -> 0 | K21: =J21*(1+Forecast!$F$2) -> 0 | L21: =K21*(1+Forecast!$F$2) -> 0 | M21: =L21*(1+Forecast!$F$2) -> 0 | N21: =M21*(1+Forecast!$F$2) -> 0 | O21: =N21*(1+Forecast!$F$2) -> 0 | P21: =O21*(1+Forecast!$F$2) -> 0 | Q21: =P21*(1+Forecast!$F$2) -> 0 | R21: =Q21*(1+Forecast!$F$2) -> 0 | ... AM21: =AL21*(1+Forecast!$F$2) -> 0
B22: Health and Wellness Expenses | J22: =F22 -> 0 | K22: =J22*(1+Forecast!$F$2) -> 0 | L22: =K22*(1+Forecast!$F$2) -> 0 | M22: =L22*(1+Forecast!$F$2) -> 0 | N22: =M22*(1+Forecast!$F$2) -> 0 | O22: =N22*(1+Forecast!$F$2) -> 0 | P22: =O22*(1+Forecast!$F$2) -> 0 | Q22: =P22*(1+Forecast!$F$2) -> 0 | R22: =Q22*(1+Forecast!$F$2) -> 0 | ... AM22: =AL22*(1+Forecast!$F$2) -> 0
C23: Gym fees, sport, other health & wellness | D23: 1100 | E23: Annually | F23: 91.67 | J23: =F23 -> 91.67 | K23: =J23*(1+Forecast!$F$2) -> 94.4201 | L23: =K23*(1+Forecast!$F$2) -> 97.252703 | M23: =L23*(1+Forecast!$F$2) -> 100.17028 | N23: =M23*(1+Forecast!$F$2) -> 103.17539 | O23: =N23*(1+Forecast!$F$2) -> 106.27065 | P23: =O23*(1+Forecast!$F$2) -> 109.45877 | Q23: =P23*(1+Forecast!$F$2) -> 112.74254 | R23: =Q23*(1+Forecast!$F$2) -> 116.12481 | ... AM23: =AL23*(1+Forecast!$F$2) -> 216.02636
C24: Private health insurance | D24: 580 | E24: Monthly | F24: 580 | J24: =F24 -> 580 | K24: =J24*(1+Forecast!$F$2) -> 597.4 | L24: =K24*(1+Forecast!$F$2) -> 615.322 | M24: =L24*(1+Forecast!$F$2) -> 633.78166 | N24: =M24*(1+Forecast!$F$2) -> 652.79511 | O24: =N24*(1+Forecast!$F$2) -> 672.37896 | P24: =O24*(1+Forecast!$F$2) -> 692.55033 | Q24: =P24*(1+Forecast!$F$2) -> 713.32684 | R24: =Q24*(1+Forecast!$F$2) -> 734.72665 | ... AM24: =AL24*(1+Forecast!$F$2) -> 1366.808
C25: Doctor, Dentist, Pharmacy, glasses | D25: 1800 | E25: Annually | F25: 150 | J25: =F25 -> 150 | K25: =J25*(1+Forecast!$F$2) -> 154.5 | L25: =K25*(1+Forecast!$F$2) -> 159.135 | M25: =L25*(1+Forecast!$F$2) -> 163.90905 | N25: =M25*(1+Forecast!$F$2) -> 168.82632 | O25: =N25*(1+Forecast!$F$2) -> 173.89111 | P25: =O25*(1+Forecast!$F$2) -> 179.10784 | Q25: =P25*(1+Forecast!$F$2) -> 184.48108 | R25: =Q25*(1+Forecast!$F$2) -> 190.01551 | ... AM25: =AL25*(1+Forecast!$F$2) -> 353.48483
C26: Life, trauma, income insurance | D26: 2200 | E26: Annually | F26: 183.33 | J26: =F26 -> 183.33 | K26: =J26*(1+Forecast!$F$2) -> 188.8299 | L26: =K26*(1+Forecast!$F$2) -> 194.4948 | M26: =L26*(1+Forecast!$F$2) -> 200.32964 | N26: =M26*(1+Forecast!$F$2) -> 206.33953 | O26: =N26*(1+Forecast!$F$2) -> 212.52972 | P26: =O26*(1+Forecast!$F$2) -> 218.90561 | Q26: =P26*(1+Forecast!$F$2) -> 225.47278 | R26: =Q26*(1+Forecast!$F$2) -> 232.23696 | ... AM26: =AL26*(1+Forecast!$F$2) -> 432.02915
B27: Transport Expenses | J27: =F27 -> 0 | K27: =J27*(1+Forecast!$F$2) -> 0 | L27: =K27*(1+Forecast!$F$2) -> 0 | M27: =L27*(1+Forecast!$F$2) -> 0 | N27: =M27*(1+Forecast!$F$2) -> 0 | O27: =N27*(1+Forecast!$F$2) -> 0 | P27: =O27*(1+Forecast!$F$2) -> 0 | Q27: =P27*(1+Forecast!$F$2) -> 0 | R27: =Q27*(1+Forecast!$F$2) -> 0 | ... AM27: =AL27*(1+Forecast!$F$2) -> 0
C28: Recreational vehicle running costs | D28: 0 | E28: 0 | F28: 0 | J28: =F28 -> 0 | K28: =J28*(1+Forecast!$F$2) -> 0 | L28: =K28*(1+Forecast!$F$2) -> 0 | M28: =L28*(1+Forecast!$F$2) -> 0 | N28: =M28*(1+Forecast!$F$2) -> 0 | O28: =N28*(1+Forecast!$F$2) -> 0 | P28: =O28*(1+Forecast!$F$2) -> 0 | Q28: =P28*(1+Forecast!$F$2) -> 0 | R28: =Q28*(1+Forecast!$F$2) -> 0 | ... AM28: =AL28*(1+Forecast!$F$2) -> 0
C29: Essential vehicle running cost | D29: 0 | E29: Annually | F29: 0 | J29: =F29 -> 0 | K29: =J29*(1+Forecast!$F$2) -> 0 | L29: =K29*(1+Forecast!$F$2) -> 0 | M29: =L29*(1+Forecast!$F$2) -> 0 | N29: =M29*(1+Forecast!$F$2) -> 0 | O29: =N29*(1+Forecast!$F$2) -> 0 | P29: =O29*(1+Forecast!$F$2) -> 0 | Q29: =P29*(1+Forecast!$F$2) -> 0 | R29: =Q29*(1+Forecast!$F$2) -> 0 | ... AM29: =AL29*(1+Forecast!$F$2) -> 0
C30: Public transport, taxis & ride share, commuting airfares | D30: 1200 | E30: Annually | F30: 100 | J30: =F30 -> 100 | K30: =J30*(1+Forecast!$F$2) -> 103 | L30: =K30*(1+Forecast!$F$2) -> 106.09 | M30: =L30*(1+Forecast!$F$2) -> 109.2727 | N30: =M30*(1+Forecast!$F$2) -> 112.55088 | O30: =N30*(1+Forecast!$F$2) -> 115.92741 | P30: =O30*(1+Forecast!$F$2) -> 119.40523 | Q30: =P30*(1+Forecast!$F$2) -> 122.98739 | R30: =Q30*(1+Forecast!$F$2) -> 126.67701 | ... AM30: =AL30*(1+Forecast!$F$2) -> 235.65655
C31: Essential vehicle insurance | D31: 0 | E31: Annually | F31: 0 | J31: =F31 -> 0 | K31: =J31*(1+Forecast!$F$2) -> 0 | L31: =K31*(1+Forecast!$F$2) -> 0 | M31: =L31*(1+Forecast!$F$2) -> 0 | N31: =M31*(1+Forecast!$F$2) -> 0 | O31: =N31*(1+Forecast!$F$2) -> 0 | P31: =O31*(1+Forecast!$F$2) -> 0 | Q31: =P31*(1+Forecast!$F$2) -> 0 | R31: =Q31*(1+Forecast!$F$2) -> 0 | ... AM31: =AL31*(1+Forecast!$F$2) -> 0
B32: Property Expenses | J32: =F32 -> 0 | K32: =J32*(1+Forecast!$F$2) -> 0 | L32: =K32*(1+Forecast!$F$2) -> 0 | M32: =L32*(1+Forecast!$F$2) -> 0 | N32: =M32*(1+Forecast!$F$2) -> 0 | O32: =N32*(1+Forecast!$F$2) -> 0 | P32: =O32*(1+Forecast!$F$2) -> 0 | Q32: =P32*(1+Forecast!$F$2) -> 0 | R32: =Q32*(1+Forecast!$F$2) -> 0 | ... AM32: =AL32*(1+Forecast!$F$2) -> 0
C33: Primary residence running costs | D33: 1780 | E33: Annually | F33: 148.33 | J33: =F33 -> 148.33 | K33: =J33*(1+Forecast!$F$2) -> 152.7799 | L33: =K33*(1+Forecast!$F$2) -> 157.3633 | M33: =L33*(1+Forecast!$F$2) -> 162.0842 | N33: =M33*(1+Forecast!$F$2) -> 166.94672 | O33: =N33*(1+Forecast!$F$2) -> 171.95512 | P33: =O33*(1+Forecast!$F$2) -> 177.11378 | Q33: =P33*(1+Forecast!$F$2) -> 182.42719 | R33: =Q33*(1+Forecast!$F$2) -> 187.90001 | ... AM33: =AL33*(1+Forecast!$F$2) -> 349.54936
C34: Primary residence body corp. | D34: 580 | E34: Quarterly | F34: 193.33 | J34: =F34 -> 193.33 | K34: =J34*(1+Forecast!$F$2) -> 199.1299 | L34: =K34*(1+Forecast!$F$2) -> 205.1038 | M34: =L34*(1+Forecast!$F$2) -> 211.25691 | N34: =M34*(1+Forecast!$F$2) -> 217.59462 | O34: =N34*(1+Forecast!$F$2) -> 224.12246 | P34: =O34*(1+Forecast!$F$2) -> 230.84613 | Q34: =P34*(1+Forecast!$F$2) -> 237.77151 | R34: =Q34*(1+Forecast!$F$2) -> 244.90466 | ... AM34: =AL34*(1+Forecast!$F$2) -> 455.59481
C35: Secondary residence running costs | D35: 0 | E35: 0 | F35: 0 | J35: =F35 -> 0 | K35: =J35*(1+Forecast!$F$2) -> 0 | L35: =K35*(1+Forecast!$F$2) -> 0 | M35: =L35*(1+Forecast!$F$2) -> 0 | N35: =M35*(1+Forecast!$F$2) -> 0 | O35: =N35*(1+Forecast!$F$2) -> 0 | P35: =O35*(1+Forecast!$F$2) -> 0 | Q35: =P35*(1+Forecast!$F$2) -> 0 | R35: =Q35*(1+Forecast!$F$2) -> 0 | ... AM35: =AL35*(1+Forecast!$F$2) -> 0
C36: Secondary residence body corp. | D36: 0 | E36: 0 | F36: 0 | J36: =F36 -> 0 | K36: =J36*(1+Forecast!$F$2) -> 0 | L36: =K36*(1+Forecast!$F$2) -> 0 | M36: =L36*(1+Forecast!$F$2) -> 0 | N36: =M36*(1+Forecast!$F$2) -> 0 | O36: =N36*(1+Forecast!$F$2) -> 0 | P36: =O36*(1+Forecast!$F$2) -> 0 | Q36: =P36*(1+Forecast!$F$2) -> 0 | R36: =Q36*(1+Forecast!$F$2) -> 0 | ... AM36: =AL36*(1+Forecast!$F$2) -> 0
C37: Investment property running costs | D37: 0 | E37: Annually | F37: =D37/12 -> 0 | J37: =F37 -> 0 | K37: =J37*(1+Forecast!$F$2) -> 0 | L37: =K37*(1+Forecast!$F$2) -> 0 | M37: =L37*(1+Forecast!$F$2) -> 0 | N37: =M37*(1+Forecast!$F$2) -> 0 | O37: =N37*(1+Forecast!$F$2) -> 0 | P37: =O37*(1+Forecast!$F$2) -> 0 | Q37: =P37*(1+Forecast!$F$2) -> 0 | R37: =Q37*(1+Forecast!$F$2) -> 0 | ... AM37: =AL37*(1+Forecast!$F$2) -> 0
B38: Other Commitments | J38: =F38 -> 0 | K38: =J38*(1+Forecast!$F$2) -> 0 | L38: =K38*(1+Forecast!$F$2) -> 0 | M38: =L38*(1+Forecast!$F$2) -> 0 | N38: =M38*(1+Forecast!$F$2) -> 0 | O38: =N38*(1+Forecast!$F$2) -> 0 | P38: =O38*(1+Forecast!$F$2) -> 0 | Q38: =P38*(1+Forecast!$F$2) -> 0 | R38: =Q38*(1+Forecast!$F$2) -> 0 | ... AM38: =AL38*(1+Forecast!$F$2) -> 0
C39: Child or spousal maintenance | D39: 0 | E39: 0 | F39: 0 | J39: =F39 -> 0 | K39: =J39*(1+Forecast!$F$2) -> 0 | L39: =K39*(1+Forecast!$F$2) -> 0 | M39: =L39*(1+Forecast!$F$2) -> 0 | N39: =M39*(1+Forecast!$F$2) -> 0 | O39: =N39*(1+Forecast!$F$2) -> 0 | P39: =O39*(1+Forecast!$F$2) -> 0 | Q39: =P39*(1+Forecast!$F$2) -> 0 | R39: =Q39*(1+Forecast!$F$2) -> 0 | ... AM39: =AL39*(1+Forecast!$F$2) -> 0
C40: Current rent expense | D40: 0 | E40: 0 | F40: 0 | J40: =F40 -> 0 | K40: =J40*(1+Forecast!$F$2) -> 0 | L40: =K40*(1+Forecast!$F$2) -> 0 | M40: =L40*(1+Forecast!$F$2) -> 0 | N40: =M40*(1+Forecast!$F$2) -> 0 | O40: =N40*(1+Forecast!$F$2) -> 0 | P40: =O40*(1+Forecast!$F$2) -> 0 | Q40: =P40*(1+Forecast!$F$2) -> 0 | R40: =Q40*(1+Forecast!$F$2) -> 0 | ... AM40: =AL40*(1+Forecast!$F$2) -> 0
...

Sheet Repayments
J2: Principal | K2: =Liabilities!E3+Liabilities!E4 -> 82426.27 | Q2: Principal | R2: =Liabilities!E10+Liabilities!E5+Liabilities!E7 -> 541251.44 | S2: All 308 loans, including top-ups on RH | X2: Principal | Y2: =Liabilities!E6+Liabilities!E9 -> 457164.26 | AE2: Principal | AF2: =Liabilities!E8+Liabilities!E11 -> 929452.01
J3: Interest rate | K3: 0.0603 | Q3: Interest rate | R3: =Liabilities!G10 -> 0.0619 | X3: Interest rate | Y3: =Liabilities!G9 -> 0.0619 | AE3: Interest rate | AF3: =Liabilities!G11 -> 0.0633
J4: Loan Term | K4: =30*12 -> 360 | Q4: Loan Term | R4: =30*12 -> 360 | X4: Loan Term | Y4: =30*12 -> 360 | AE4: Loan Term | AF4: =30*12 -> 360
D5: Start Payment | E5: 46203 | J5: Compound Periods per Year | K5: 12 | Q5: Annual compounding periods | R5: 12 | X5: Annual compounding periods | Y5: 12 | AE5: Annual compounding periods | AF5: 12
J6: Monthly Repayment | K6: =Liabilities!H3+Liabilities!H4 -> 1638 | Q6: Monthly Repayment | R6: =Liabilities!H10+Liabilities!H7+Liabilities!H5 -> 3781 | X6: Monthly Repayment | Y6: =Liabilities!H6+Liabilities!H9 -> 2884 | AE6: Monthly Repayment | AF6: =Liabilities!H8+Liabilities!H11 -> 6042 | AP6: Monthly Repayment | AQ6: =K6+R6+Y6 -> 8303
I7: PPOR | P7: Wentworthville | W7: Black Diamond | AD7: Shane St
D8: Payment # | E8: Financial Year | F8: Payment Date | G8: Month | H8: # of Days | I8: Loan Type | J8: Starting Balance | K8: Monthly Interest | L8: Monthly Principal | M8: Offset | N8: Ending Balance | P8: Loan Type | Q8: Starting Balance | R8: Monthly Interest | S8: Monthly Principal | T8: Offset | U8: Ending Balance | W8: Loan Type | X8: Starting Balance | Y8: Monthly Interest | Z8: Monthly Principal | AA8: Offset | AB8: Ending Balance | AD8: Loan Type | AE8: Starting Balance | AF8: Monthly Interest | AG8: Monthly Principal | AH8: Offset | AI8: Ending Balance | AK8: Financial Year | AL8: Calendar Month | AM8: 308 Interest | AN8: BD Interest | AO8: Shane Interest | AP8: Personal Interest | AQ8: Personal Repayments | AR8: Personal Owing | AS8: Total Interest | AT8: Total Principal | AU8: Total Repayments | AV8: Total Owing
D9: 1 | E9: =IF(MONTH(EDATE($E$5,D9))<7,YEAR(EDATE($E$5,D9)),YEAR(EDATE($E$5,D9))+1) -> 2027 | F9: =EDATE($E$5,D9) -> 46233 | G9: =MONTH(F9) -> 7 | H9: =DAY(EOMONTH(F9,0)) -> 31 | I9: PI | J9: =K2 -> 82426.27 | K9: =(IF(I9="PI",J9,IF(ISNUMBER(N8),N8,J9))*$K$3/365*$H9*IF(J9>0,1,0)) -> 422.13542 | L9: =IF(I9="IO",0,$K$6-K9)*IF(J9>0,1,0) -> 1215.8646 | M9: =IF(I9="IO",$K$6-K9+IF(ISNUMBER(M8),M8,0),IF(ISNUMBER(M8),M8,0)) -> 0 | N9: =(J9+K9-$K$6-IF(I9="PI",0,M9))*IF(J9>0,1,0) -> 81210.405 | P9: PI | Q9: =R2 -> 541251.44 | R9: =(IF(P9="PI",Q9,IF(ISNUMBER(U8),U8,Q9))*$R$3/365*$H9*IF(Q9>0,1,0)) -> 2845.4997 | S9: =IF(P9="IO",0,$R$6-R9)*IF(Q9>0,1,0) -> 935.50031 | T9: =IF(P9="IO",$R$6-R9+IF(ISNUMBER(T8),T8,0),IF(ISNUMBER(T8),T8,0)) -> 0 | U9: =(Q9+R9-$R$6-IF(P9="PI",0,T9))*IF(Q9>0,1,0) -> 540315.94 | W9: PI | X9: =Y2 -> 457164.26 | Y9: =(IF(W9="PI",X9,IF(ISNUMBER(AB8),AB8,X9))*$Y$3/365*$H9*IF(X9>0,1,0)) -> 2403.4315 | Z9: =IF(W9="IO",0,$Y$6-Y9)*IF(X9>0,1,0) -> 480.5685 | AA9: =IF(W9="IO",$Y$6-Y9+IF(ISNUMBER(AA8),AA8,0),IF(ISNUMBER(AA8),AA8,0)) -> 0 | AB9: =(X9+Y9-$Y$6-IF(W9="PI",0,AA9))*IF(X9>0,1,0) -> 456683.69 | AD9: PI | AE9: =AF2 -> 929452.01 | AF9: =(IF(AD9="PI",AE9,IF(ISNUMBER(AI8),AI8,AE9))*$AF$3/365*$H9*IF(AE9>0,1,0)) -> 4996.8868 | AG9: =IF(AD9="IO",0,$AF$6-AF9)*IF(AE9>0,1,0) -> 1045.1132 | AH9: =IF(AD9="IO",$AF$6-AF9+IF(ISNUMBER(AH8),AH8,0),IF(ISNUMBER(AH8),AH8,0)) -> 0 | AI9: =(AE9+AF9-$AF$6-IF(AD9="PI",0,AH9))*IF(AE9>0,1,0) -> 928406.9 | AK9: =E9 -> 2027 | AL9: =G9 -> 7 | AM9: =R9 -> 2845.4997 | AN9: =Y9 -> 2403.4315 | AO9: =AF9 -> 4996.8868 | AP9: =AM9+AN9 -> 5248.9312 | AQ9: =K6+R6+Y6 -> 8303 | AR9: =N9+U9+AB9 -> 1078210 | AS9: =AP9+AO9 -> 10245.818 | AT9: =L9+S9+Z9+AG9 -> 3677.0466 | AU9: =AS9+AT9 -> 13922.865 | AV9: =N9+U9+AB9+AI9 -> 2006616.9 | AY9: Calendar Month | AZ9: 6
D10: =D9+1 -> 2 | E10: =IF(MONTH(EDATE($E$5,D10))<7,YEAR(EDATE($E$5,D10)),YEAR(EDATE($E$5,D10))+1) -> 2027 | F10: =EDATE($E$5,D10) -> 46264 | G10: =MONTH(F10) -> 8 | H10: =DAY(EOMONTH(F10,0)) -> 31 | I10: PI | J10: =IF(I10="PI",IF(N9<=0,0,N9),(IF(I10="IO",J9,"")))*IF(N9<=0,0,1) -> 81210.405 | K10: =(IF(I10="PI",J10,IF(ISNUMBER(N9),N9,J10))*$K$3/365*$H10*IF(J10>0,1,0)) -> 415.90852 | L10: =IF(I10="IO",0,$K$6-K10)*IF(J10>0,1,0) -> 1222.0915 | M10: =IF(I10="IO",$K$6-K10+IF(ISNUMBER(M9),M9,0),IF(ISNUMBER(M9),M9,0)) -> 0 | N10: =(J10+K10-$K$6-IF(I10="PI",0,M10))*IF(J10>0,1,0) -> 79988.314 | P10: PI | Q10: =IF(P10="PI",IF(U9<=0,0,U9),(IF(P10="IO",Q9,"")))*IF(U9<=0,0,1) -> 540315.94 | R10: =(IF(P10="PI",Q10,IF(ISNUMBER(U9),U9,Q10))*$R$3/365*$H10*IF(Q10>0,1,0)) -> 2840.5815 | S10: =IF(P10="IO",0,$R$6-R10)*IF(Q10>0,1,0) -> 940.41847 | T10: =IF(P10="IO",$R$6-R10+IF(ISNUMBER(T9),T9,0),IF(ISNUMBER(T9),T9,0)) -> 0 | U10: =(Q10+R10-$R$6-IF(P10="PI",0,T10))*IF(Q10>0,1,0) -> 539375.52 | W10: PI | X10: =IF(W10="PI",IF(AB9<=0,0,AB9),(IF(W10="IO",X9,"")))*IF(AB9<=0,0,1) -> 456683.69 | Y10: =(IF(W10="PI",X10,IF(ISNUMBER(AB9),AB9,X10))*$Y$3/365*$H10*IF(X10>0,1,0)) -> 2400.905 | Z10: =IF(W10="IO",0,$Y$6-Y10)*IF(X10>0,1,0) -> 483.09497 | AA10: =IF(W10="IO",$Y$6-Y10+IF(ISNUMBER(AA9),AA9,0),IF(ISNUMBER(AA9),AA9,0)) -> 0 | AB10: =(X10+Y10-$Y$6-IF(W10="PI",0,AA10))*IF(X10>0,1,0) -> 456200.6 | AD10: PI | AE10: =IF(AD10="PI",IF(AI9<=0,0,AI9),(IF(AD10="IO",AE9,"")))*IF(AI9<=0,0,1) -> 928406.9 | AF10: =(IF(AD10="PI",AE10,IF(ISNUMBER(AI9),AI9,AE10))*$AF$3/365*$H10*IF(AE10>0,1,0)) -> 4991.2681 | AG10: =IF(AD10="IO",0,$AF$6-AF10)*IF(AE10>0,1,0) -> 1050.7319 | AH10: =IF(AD10="IO",$AF$6-AF10+IF(ISNUMBER(AH9),AH9,0),IF(ISNUMBER(AH9),AH9,0)) -> 0 | AI10: =(AE10+AF10-$AF$6-IF(AD10="PI",0,AH10))*IF(AE10>0,1,0) -> 927356.16 | AK10: =E10 -> 2027 | AL10: =G10 -> 8 | AM10: =IF($AK10=$AK9,R10+AM9,R10) -> 5686.0812 | AN10: =IF($AK10=$AK9,Y10+AN9,Y10) -> 4804.3365 | AO10: =IF($AK10=$AK9,AF10+AO9,AF10) -> 9988.1549 | AP10: =AM10+AN10 -> 10490.418 | AQ10: =IF(AK10=AK9,AQ9,0)+ IF(J10>0,$K$6,0)+ IF(Q10>0,$R$6,0)+ IF(X10>0,$Y$6,0) -> 16606 | AR10: =N10+U10+AB10 -> 1075564.4 | AS10: =AP10+AO10 -> 20478.573 | AT10: =IF(AK10=AK9,AT9,0)+ IF(J10>0,L10,0)+ IF(Q10>0,S10,0)+ IF(X10>0,Z10,0)+ IF(AE10>0,AG10,0) -> 7373.3834 | AU10: =AS10+AT10 -> 27851.956 | AV10: =N10+U10+AB10+AI10 -> 2002920.6
D11: =D10+1 -> 3 | E11: =IF(MONTH(EDATE($E$5,D11))<7,YEAR(EDATE($E$5,D11)),YEAR(EDATE($E$5,D11))+1) -> 2027 | F11: =EDATE($E$5,D11) -> 46295 | G11: =MONTH(F11) -> 9 | H11: =DAY(EOMONTH(F11,0)) -> 30 | I11: PI | J11: =IF(I11="PI",IF(N10<=0,0,N10),(IF(I11="IO",J10,"")))*IF(N10<=0,0,1) -> 79988.314 | K11: =(IF(I11="PI",J11,IF(ISNUMBER(N10),N10,J11))*$K$3/365*$H11*IF(J11>0,1,0)) -> 396.43523 | L11: =IF(I11="IO",0,$K$6-K11)*IF(J11>0,1,0) -> 1241.5648 | M11: =IF(I11="IO",$K$6-K11+IF(ISNUMBER(M10),M10,0),IF(ISNUMBER(M10),M10,0)) -> 0 | N11: =(J11+K11-$K$6-IF(I11="PI",0,M11))*IF(J11>0,1,0) -> 78746.749 | P11: PI | Q11: =IF(P11="PI",IF(U10<=0,0,U10),(IF(P11="IO",Q10,"")))*IF(U10<=0,0,1) -> 539375.52 | R11: =(IF(P11="PI",Q11,IF(ISNUMBER(U10),U10,Q11))*$R$3/365*$H11*IF(Q11>0,1,0)) -> 2744.1653 | S11: =IF(P11="IO",0,$R$6-R11)*IF(Q11>0,1,0) -> 1036.8347 | T11: =IF(P11="IO",$R$6-R11+IF(ISNUMBER(T10),T10,0),IF(ISNUMBER(T10),T10,0)) -> 0 | U11: =(Q11+R11-$R$6-IF(P11="PI",0,T11))*IF(Q11>0,1,0) -> 538338.69 | W11: PI | X11: =IF(W11="PI",IF(AB10<=0,0,AB10),(IF(W11="IO",X10,"")))*IF(AB10<=0,0,1) -> 456200.6 | Y11: =(IF(W11="PI",X11,IF(ISNUMBER(AB10),AB10,X11))*$Y$3/365*$H11*IF(X11>0,1,0)) -> 2320.9987 | Z11: =IF(W11="IO",0,$Y$6-Y11)*IF(X11>0,1,0) -> 563.00135 | AA11: =IF(W11="IO",$Y$6-Y11+IF(ISNUMBER(AA10),AA10,0),IF(ISNUMBER(AA10),AA10,0)) -> 0 | AB11: =(X11+Y11-$Y$6-IF(W11="PI",0,AA11))*IF(X11>0,1,0) -> 455637.6 | AD11: PI | AE11: =IF(AD11="PI",IF(AI10<=0,0,AI10),(IF(AD11="IO",AE10,"")))*IF(AI10<=0,0,1) -> 927356.16 | AF11: =(IF(AD11="PI",AE11,IF(ISNUMBER(AI10),AI10,AE11))*$AF$3/365*$H11*IF(AE11>0,1,0)) -> 4824.7928 | AG11: =IF(AD11="IO",0,$AF$6-AF11)*IF(AE11>0,1,0) -> 1217.2072 | AH11: =IF(AD11="IO",$AF$6-AF11+IF(ISNUMBER(AH10),AH10,0),IF(ISNUMBER(AH10),AH10,0)) -> 0 | AI11: =(AE11+AF11-$AF$6-IF(AD11="PI",0,AH11))*IF(AE11>0,1,0) -> 926138.96 | AK11: =E11 -> 2027 | AL11: =G11 -> 9 | AM11: =IF($AK11=$AK10,R11+AM10,R11) -> 8430.2465 | AN11: =IF($AK11=$AK10,Y11+AN10,Y11) -> 7125.3352 | AO11: =IF($AK11=$AK10,AF11+AO10,AF11) -> 14812.948 | AP11: =AM11+AN11 -> 15555.582 | AQ11: =IF(AK11=AK10,AQ10,0)+ IF(J11>0,$K$6,0)+ IF(Q11>0,$R$6,0)+ IF(X11>0,$Y$6,0) -> 24909 | AR11: =N11+U11+AB11 -> 1072723 | AS11: =AM11+AN11+AO11 -> 30368.529 | AT11: =IF(AK11=AK10,AT10,0)+ IF(J11>0,L11,0)+ IF(Q11>0,S11,0)+ IF(X11>0,Z11,0)+ IF(AE11>0,AG11,0) -> 11431.991 | AU11: =AS11+AT11 -> 41800.521 | AV11: =N11+U11+AB11+AI11 -> 1998862 | AZ11: Column Labels
D12: =D11+1 -> 4 | E12: =IF(MONTH(EDATE($E$5,D12))<7,YEAR(EDATE($E$5,D12)),YEAR(EDATE($E$5,D12))+1) -> 2027 | F12: =EDATE($E$5,D12) -> 46325 | G12: =MONTH(F12) -> 10 | H12: =DAY(EOMONTH(F12,0)) -> 31 | I12: PI | J12: =IF(I12="PI",IF(N11<=0,0,N11),(IF(I12="IO",J11,"")))*IF(N11<=0,0,1) -> 78746.749 | K12: =(IF(I12="PI",J12,IF(ISNUMBER(N11),N11,J12))*$K$3/365*$H12*IF(J12>0,1,0)) -> 403.29123 | L12: =IF(I12="IO",0,$K$6-K12)*IF(J12>0,1,0) -> 1234.7088 | M12: =IF(I12="IO",$K$6-K12+IF(ISNUMBER(M11),M11,0),IF(ISNUMBER(M11),M11,0)) -> 0 | N12: =(J12+K12-$K$6-IF(I12="PI",0,M12))*IF(J12>0,1,0) -> 77512.04 | P12: PI | Q12: =IF(P12="PI",IF(U11<=0,0,U11),(IF(P12="IO",Q11,"")))*IF(U11<=0,0,1) -> 538338.69 | R12: =(IF(P12="PI",Q12,IF(ISNUMBER(U11),U11,Q12))*$R$3/365*$H12*IF(Q12>0,1,0)) -> 2830.1866 | S12: =IF(P12="IO",0,$R$6-R12)*IF(Q12>0,1,0) -> 950.81341 | T12: =IF(P12="IO",$R$6-R12+IF(ISNUMBER(T11),T11,0),IF(ISNUMBER(T11),T11,0)) -> 0 | U12: =(Q12+R12-$R$6-IF(P12="PI",0,T12))*IF(Q12>0,1,0) -> 537387.87 | W12: PI | X12: =IF(W12="PI",IF(AB11<=0,0,AB11),(IF(W12="IO",X11,"")))*IF(AB11<=0,0,1) -> 455637.6 | Y12: =(IF(W12="PI",X12,IF(ISNUMBER(AB11),AB11,X12))*$Y$3/365*$H12*IF(X12>0,1,0)) -> 2395.4054 | Z12: =IF(W12="IO",0,$Y$6-Y12)*IF(X12>0,1,0) -> 488.59457 | AA12: =IF(W12="IO",$Y$6-Y12+IF(ISNUMBER(AA11),AA11,0),IF(ISNUMBER(AA11),AA11,0)) -> 0 | AB12: =(X12+Y12-$Y$6-IF(W12="PI",0,AA12))*IF(X12>0,1,0) -> 455149 | AD12: PI | AE12: =IF(AD12="PI",IF(AI11<=0,0,AI11),(IF(AD12="IO",AE11,"")))*IF(AI11<=0,0,1) -> 926138.96 | AF12: =(IF(AD12="PI",AE12,IF(ISNUMBER(AI11),AI11,AE12))*$AF$3/365*$H12*IF(AE12>0,1,0)) -> 4979.0753 | AG12: =IF(AD12="IO",0,$AF$6-AF12)*IF(AE12>0,1,0) -> 1062.9247 | AH12: =IF(AD12="IO",$AF$6-AF12+IF(ISNUMBER(AH11),AH11,0),IF(ISNUMBER(AH11),AH11,0)) -> 0 | AI12: =(AE12+AF12-$AF$6-IF(AD12="PI",0,AH12))*IF(AE12>0,1,0) -> 925076.03 | AK12: =E12 -> 2027 | AL12: =G12 -> 10 | AM12: =IF($AK12=$AK11,R12+AM11,R12) -> 11260.433 | AN12: =IF($AK12=$AK11,Y12+AN11,Y12) -> 9520.7406 | AO12: =IF($AK12=$AK11,AF12+AO11,AF12) -> 19792.023 | AP12: =AM12+AN12 -> 20781.174 | AQ12: =IF(AK12=AK11,AQ11,0)+ IF(J12>0,$K$6,0)+ IF(Q12>0,$R$6,0)+ IF(X12>0,$Y$6,0) -> 33212 | AR12: =N12+U12+AB12 -> 1070048.9 | AS12: =IF($AK12=$AK11,AF12+AP11,AP11) -> 20534.657 | AT12: =IF(AK12=AK11,AT11,0)+ IF(J12>0,L12,0)+ IF(Q12>0,S12,0)+ IF(X12>0,Z12,0)+ IF(AE12>0,AG12,0) -> 15169.033 | AU12: =AS12+AT12 -> 35703.69 | AV12: =N12+U12+AB12+AI12 -> 1995124.9 | AZ12: 2027 | BA12: 2028 | BB12: 2029 | BC12: 2030 | BD12: 2031 | BE12: 2032 | BF12: 2033 | BG12: 2034 | BH12: 2035 | BI12: 2036 | BJ12: 2037 | BK12: 2038 | BL12: 2039 | BM12: 2040 | BN12: 2041 | BO12: 2042 | BP12: 2043 | BQ12: 2044 | BR12: 2045 | BS12: 2046 | BT12: 2047 | BU12: 2048 | BV12: 2049 | BW12: 2050 | BX12: 2051 | BY12: 2052 | BZ12: 2053 | CA12: 2054 | CB12: 2055
D13: =D12+1 -> 5 | E13: =IF(MONTH(EDATE($E$5,D13))<7,YEAR(EDATE($E$5,D13)),YEAR(EDATE($E$5,D13))+1) -> 2027 | F13: =EDATE($E$5,D13) -> 46356 | G13: =MONTH(F13) -> 11 | H13: =DAY(EOMONTH(F13,0)) -> 30 | I13: PI | J13: =IF(I13="PI",IF(N12<=0,0,N12),(IF(I13="IO",J12,"")))*IF(N12<=0,0,1) -> 77512.04 | K13: =(IF(I13="PI",J13,IF(ISNUMBER(N12),N12,J13))*$K$3/365*$H13*IF(J13>0,1,0)) -> 384.16241 | L13: =IF(I13="IO",0,$K$6-K13)*IF(J13>0,1,0) -> 1253.8376 | M13: =IF(I13="IO",$K$6-K13+IF(ISNUMBER(M12),M12,0),IF(ISNUMBER(M12),M12,0)) -> 0 | N13: =(J13+K13-$K$6-IF(I13="PI",0,M13))*IF(J13>0,1,0) -> 76258.203 | P13: PI | Q13: =IF(P13="PI",IF(U12<=0,0,U12),(IF(P13="IO",Q12,"")))*IF(U12<=0,0,1) -> 537387.87 | R13: =(IF(P13="PI",Q13,IF(ISNUMBER(U12),U12,Q13))*$R$3/365*$H13*IF(Q13>0,1,0)) -> 2734.0528 | S13: =IF(P13="IO",0,$R$6-R13)*IF(Q13>0,1,0) -> 1046.9472 | T13: =IF(P13="IO",$R$6-R13+IF(ISNUMBER(T12),T12,0),IF(ISNUMBER(T12),T12,0)) -> 0 | U13: =(Q13+R13-$R$6-IF(P13="PI",0,T13))*IF(Q13>0,1,0) -> 536340.93 | W13: PI | X13: =IF(W13="PI",IF(AB12<=0,0,AB12),(IF(W13="IO",X12,"")))*IF(AB12<=0,0,1) -> 455149 | Y13: =(IF(W13="PI",X13,IF(ISNUMBER(AB12),AB12,X13))*$Y$3/365*$H13*IF(X13>0,1,0)) -> 2315.6485 | Z13: =IF(W13="IO",0,$Y$6-Y13)*IF(X13>0,1,0) -> 568.35152 | AA13: =IF(W13="IO",$Y$6-Y13+IF(ISNUMBER(AA12),AA12,0),IF(ISNUMBER(AA12),AA12,0)) -> 0 | AB13: =(X13+Y13-$Y$6-IF(W13="PI",0,AA13))*IF(X13>0,1,0) -> 454580.65 | AD13: PI | AE13: =IF(AD13="PI",IF(AI12<=0,0,AI12),(IF(AD13="IO",AE12,"")))*IF(AI12<=0,0,1) -> 925076.03 | AF13: =(IF(AD13="PI",AE13,IF(ISNUMBER(AI12),AI12,AE13))*$AF$3/365*$H13*IF(AE13>0,1,0)) -> 4812.9298 | AG13: =IF(AD13="IO",0,$AF$6-AF13)*IF(AE13>0,1,0) -> 1229.0702 | AH13: =IF(AD13="IO",$AF$6-AF13+IF(ISNUMBER(AH12),AH12,0),IF(ISNUMBER(AH12),AH12,0)) -> 0 | AI13: =(AE13+AF13-$AF$6-IF(AD13="PI",0,AH13))*IF(AE13>0,1,0) -> 923846.96 | AK13: =E13 -> 2027 | AL13: =G13 -> 11 | AM13: =IF($AK13=$AK12,R13+AM12,R13) -> 13994.486 | AN13: =IF($AK13=$AK12,Y13+AN12,Y13) -> 11836.389 | AO13: =IF($AK13=$AK12,AF13+AO12,AF13) -> 24604.953 | AP13: =AM13+AN13 -> 25830.875 | AQ13: =IF(AK13=AK12,AQ12,0)+ IF(J13>0,$K$6,0)+ IF(Q13>0,$R$6,0)+ IF(X13>0,$Y$6,0) -> 41515 | AR13: =N13+U13+AB13 -> 1067179.8 | AS13: =AP13+AO13 -> 50435.828 | AT13: =IF(AK13=AK12,AT12,0)+ IF(J13>0,L13,0)+ IF(Q13>0,S13,0)+ IF(X13>0,Z13,0)+ IF(AE13>0,AG13,0) -> 19267.239 | AU13: =AS13+AT13 -> 69703.067 | AV13: =N13+U13+AB13+AI13 -> 1991026.7 | AX13: Owing | AY13: Sum of Total Owing | AZ13: 1962440.7 | BA13: 1911882.6 | BB13: 1857771.6 | BC13: 1800219.6 | BD13: 1742007.4 | BE13: 1697595.4 | BF13: 1650026.1 | BG13: 1599396.9 | BH13: 1545510.8 | BI13: 1488423.4 | BJ13: 1427398.7 | BK13: 1362448.5 | BL13: 1293320.1 | BM13: 1219964 | BN13: 1141669.7 | BO13: 1058338.7 | BP13: 969647.02 | BQ13: 875410.19 | BR13: 774950.51 | BS13: 668028.05 | BT13: 554227 | BU13: 444938.04 | BV13: 363453.3 | BW13: 276695.62 | BX13: 184323.74 | BY13: 85996.68 | BZ13: 20593.323 | CA13: 0 | CB13: 0
